<robot
  name="Assem00">
  <link
    name="base_link">
    <inertial>
      <origin
        xyz="1.9009E-18 -3.3542E-18 0.049155"
        rpy="0 0 0" />
      <mass
        value="7.0765" />
      <inertia
        ixx="0"
        ixy="0"
        ixz="0"
        iyy="0"
        iyz="0"
        izz="0" />
    </inertial>
    <visual>
      <origin
        xyz="0 0 0"
        rpy="0 0 0" />
      <geometry>
        <mesh
          filename="package://Assem00/meshes/base_link.STL" />
      </geometry>
      <material
        name="">
        <color
          rgba="0.77647 0.75686 0.73725 1" />
      </material>
    </visual>
    <collision>
      <origin
        xyz="0 0 0"
        rpy="0 0 0" />
      <geometry>
        <mesh
          filename="package://Assem00/meshes/base_link.STL" />
      </geometry>
    </collision>
  </link>
  <link
    name="Link00">
    <inertial>
      <origin
        xyz="6.9389E-18 0.075 -0.005"
        rpy="0 0 0" />
      <mass
        value="0.041843" />
      <inertia
        ixx="0"
        ixy="0"
        ixz="0"
        iyy="0"
        iyz="0"
        izz="0" />
    </inertial>
    <visual>
      <origin
        xyz="0 0 0"
        rpy="0 0 0" />
      <geometry>
        <mesh
          filename="package://Assem00/meshes/Link00.STL" />
      </geometry>
      <material
        name="">
        <color
          rgba="0.79216 0.81961 0.93333 1" />
      </material>
    </visual>
    <collision>
      <origin
        xyz="0 0 0"
        rpy="0 0 0" />
      <geometry>
        <mesh
          filename="package://Assem00/meshes/Link00.STL" />
      </geometry>
    </collision>
  </link>
  <joint
    name="Joint00"
    type="revolute">
    <origin
      xyz="0 -0.13 0"
      rpy="1.5708 -0.5539 3.1416" />
    <parent
      link="base_link" />
    <child
      link="Link00" />
    <axis
      xyz="0 0 -1" />
    <limit
      effort="0"
      velocity="0" />
  </joint>
  <link
    name="Link01">
    <inertial>
      <origin
        xyz="2.7756E-17 0.1 -0.005"
        rpy="0 0 0" />
      <mass
        value="0.054343" />
      <inertia
        ixx="0"
        ixy="0"
        ixz="0"
        iyy="0"
        iyz="0"
        izz="0" />
    </inertial>
    <visual>
      <origin
        xyz="0 0 0"
        rpy="0 0 0" />
      <geometry>
        <mesh
          filename="package://Assem00/meshes/Link01.STL" />
      </geometry>
      <material
        name="">
        <color
          rgba="0.79216 0.81961 0.93333 1" />
      </material>
    </visual>
    <collision>
      <origin
        xyz="0 0 0"
        rpy="0 0 0" />
      <geometry>
        <mesh
          filename="package://Assem00/meshes/Link01.STL" />
      </geometry>
    </collision>
  </link>
  <joint
    name="Joint01"
    type="revolute">
    <origin
      xyz="0 0.15 -0.01"
      rpy="0 0 -1.3928" />
    <parent
      link="Link00" />
    <child
      link="Link01" />
    <axis
      xyz="0 0 -1" />
    <limit
      effort="0"
      velocity="0" />
  </joint>
</robot>